<?xml version="1.0" ?>
  <robot name="Frames" xmlns:xacro="http://www.ros.org/wiki/xacro">

  <link name="frames_base_link">
    <inertial>
      <origin xyz="0.0005040855085333166 -0.010273094086501193 0.03542491363637938" rpy="0 0 0"/>
      <mass value="1.5130327428354182"/>
      <inertia ixx="0.001983" iyy="0.002709" izz="0.002959" ixy="6e-06" iyz="-3.5e-05" ixz="3e-05"/>
    </inertial>
    <visual>
      <origin xyz="0 0 0" rpy="0 0 0"/>
      <geometry>
        <mesh filename="package://frames_description/meshes/frames_base_link.stl" scale="0.001 0.001 0.001"/>
      </geometry>
    </visual>
    <collision>
      <origin xyz="0 0 0" rpy="0 0 0"/>
      <geometry>
        <mesh filename="package://frames_description/meshes/frames_base_link.stl" scale="0.001 0.001 0.001"/>
      </geometry>
    </collision>
  </link>

  <link name="frames_link1">
    <inertial>
      <origin xyz="-3.404725774509886e-05 -2.1010427580299316e-11 0.013790395795608756" rpy="0 0 0"/>
      <mass value="0.18511181553011938"/>
      <inertia ixx="5e-05" iyy="0.000101" izz="9.7e-05" ixy="-0.0" iyz="-0.0" ixz="0.0"/>
    </inertial>
    <visual>
      <origin xyz="0.00055 0.0 -0.0886" rpy="0 0 0"/>
      <geometry>
        <mesh filename="package://frames_description/meshes/frames_link1.stl" scale="0.001 0.001 0.001"/>
      </geometry>
    </visual>
    <collision>
      <origin xyz="0.00055 0.0 -0.0886" rpy="0 0 0"/>
      <geometry>
        <mesh filename="package://frames_description/meshes/frames_link1.stl" scale="0.001 0.001 0.001"/>
      </geometry>
    </collision>
  </link>

  <link name="frames_link2">
    <inertial>
      <origin xyz="0.025124340773863555 0.00015918221692612635 0.06025458578533169" rpy="0 0 0"/>
      <mass value="0.37661185911242273"/>
      <inertia ixx="0.000699" iyy="0.000674" izz="0.000137" ixy="1e-06" iyz="0.0" ixz="0.0"/>
    </inertial>
    <visual>
      <origin xyz="0.02705 0.0 -0.1126" rpy="0 0 0"/>
      <geometry>
        <mesh filename="package://frames_description/meshes/frames_link2.stl" scale="0.001 0.001 0.001"/>
      </geometry>
    </visual>
    <collision>
      <origin xyz="0.02705 0.0 -0.1126" rpy="0 0 0"/>
      <geometry>
        <mesh filename="package://frames_description/meshes/frames_link2.stl" scale="0.001 0.001 0.001"/>
      </geometry>
    </collision>
  </link>

  <link name="frames_link3">
    <inertial>
      <origin xyz="0.02652087793939466 0.00010090442859749642 0.02719951130554263" rpy="0 0 0"/>
      <mass value="0.3445625469275287"/>
      <inertia ixx="0.000203" iyy="0.000289" izz="0.00017" ixy="0.0" iyz="0.0" ixz="0.0"/>
    </inertial>
    <visual>
      <origin xyz="0.02705 0.0 -0.2331" rpy="0 0 0"/>
      <geometry>
        <mesh filename="package://frames_description/meshes/frames_link3.stl" scale="0.001 0.001 0.001"/>
      </geometry>
    </visual>
    <collision>
      <origin xyz="0.02705 0.0 -0.2331" rpy="0 0 0"/>
      <geometry>
        <mesh filename="package://frames_description/meshes/frames_link3.stl" scale="0.001 0.001 0.001"/>
      </geometry>
    </collision>
  </link>

  <link name="frames_link4">
    <inertial>
      <origin xyz="-1.518206498092329e-06 0.04461577742036456 1.3239624671035344e-06" rpy="0 0 0"/>
      <mass value="0.39024457935082074"/>
      <inertia ixx="0.000389" iyy="9.2e-05" izz="0.000401" ixy="-3e-06" iyz="-0.0" ixz="-0.0"/>
    </inertial>
    <visual>
      <origin xyz="0.00055 -0.01825 -0.29035" rpy="0 0 0"/>
      <geometry>
        <mesh filename="package://frames_description/meshes/frames_link4.stl" scale="0.001 0.001 0.001"/>
      </geometry>
    </visual>
    <collision>
      <origin xyz="0.00055 -0.01825 -0.29035" rpy="0 0 0"/>
      <geometry>
        <mesh filename="package://frames_description/meshes/frames_link4.stl" scale="0.001 0.001 0.001"/>
      </geometry>
    </collision>
  </link>

  <link name="frames_link5">
    <inertial>
      <origin xyz="0.012643550717544487 0.02709385501657724 -0.003236084058836186" rpy="0 0 0"/>
      <mass value="0.07930924998218244"/>
      <inertia ixx="5e-05" iyy="2.4e-05" izz="4.2e-05" ixy="-1e-06" iyz="4e-06" ixz="0.0"/>
    </inertial>
    <visual>
      <origin xyz="0.01505 -0.12345 -0.29035" rpy="0 0 0"/>
      <geometry>
        <mesh filename="package://frames_description/meshes/frames_link5.stl" scale="0.001 0.001 0.001"/>
      </geometry>
    </visual>
    <collision>
      <origin xyz="0.01505 -0.12345 -0.29035" rpy="0 0 0"/>
      <geometry>
        <mesh filename="package://frames_description/meshes/frames_link5.stl" scale="0.001 0.001 0.001"/>
      </geometry>
    </collision>
  </link>

  <link name="frames_link6">
    <inertial>
      <origin xyz="2.1560285923477931e-07 0.0018489662859189626 6.665609375566817e-08" rpy="0 0 0"/>
      <mass value="0.007968295840693102"/>
      <inertia ixx="0.0" iyy="0.0" izz="0.0" ixy="0.0" iyz="-0.0" ixz="0.0"/>
    </inertial>
    <visual>
      <origin xyz="0.00205 -0.17915 -0.26985" rpy="0 0 0"/>
      <geometry>
        <mesh filename="package://frames_description/meshes/frames_link6.stl" scale="0.001 0.001 0.001"/>
      </geometry>
    </visual>
    <collision>
      <origin xyz="0.00205 -0.17915 -0.26985" rpy="0 0 0"/>
      <geometry>
        <mesh filename="package://frames_description/meshes/frames_link6.stl" scale="0.001 0.001 0.001"/>
      </geometry>
    </collision>
  </link>

  <joint name="frames_joint1" type="revolute">
    <origin xyz="-0.00055 0.0 0.0886" rpy="0 0 0"/>
    <parent link="frames_base_link"/>
    <child link="frames_link1"/>
    <axis xyz="0.0 -0.0 -1.0"/>
    <limit effort="87" lower="-1.57" upper="1.57" velocity="2.3925" />
  </joint>

  <joint name="frames_joint2" type="revolute">
    <origin xyz="-0.0265 0.0 0.024" rpy="0 0 0"/>
    <parent link="frames_link1"/>
    <child link="frames_link2"/>
    <axis xyz="1.0 0.0 0.0"/>
    <limit effort="87" lower="-1.57" upper="1.57" velocity="2.3925" />
  </joint>

  <joint name="frames_joint3" type="revolute">
    <origin xyz="0.0 0.0 0.1205" rpy="0 0 0"/>
    <parent link="frames_link2"/>
    <child link="frames_link3"/>
    <axis xyz="1.0 0.0 0.0"/>
    <limit effort="87" lower="-1.57" upper="1.57" velocity="2.3925" />
  </joint>

  <joint name="frames_joint4" type="revolute">
    <origin xyz="0.0265 0.01825 0.05725" rpy="0 0 0"/>
    <parent link="frames_link3"/>
    <child link="frames_link4"/>
    <axis xyz="0.0 -1.0 -0.0"/>
    <limit effort="87" lower="-1.57" upper="1.57" velocity="2.3925" />
  </joint>

  <joint name="frames_joint5" type="revolute">
    <origin xyz="-0.0145 0.1052 0.0" rpy="0 0 0"/>
    <parent link="frames_link4"/>
    <child link="frames_link5"/>
    <axis xyz="1.0 -0.0 -0.0"/>
    <limit effort="87" lower="-1.57" upper="1.57" velocity="2.3925" />
  </joint>

  <joint name="frames_joint6" type="revolute">
    <origin xyz="0.013 0.0557 -0.0205" rpy="0 0 0"/>
    <parent link="frames_link5"/>
    <child link="frames_link6"/>
    <axis xyz="-0.0 -1.0 0.0"/>
    <limit effort="87" lower="-1.57" upper="1.57" velocity="2.3925" />
  </joint>
</robot>
